<?xml version="1.0" encoding="UTF-8"?>
<robot name="formular_car">
    <material name="tire_color">
        <color rgba="0.2 0.2 0.2 1.0"/>
    </material>
    <material name="body_color">
        <color rgba="0.9 0.9 0.9 1.0"/>
    </material>

    <!--* Body Link  -->
    <link name="body">
        <inertial>
            <mass value="800.0"/>
            <origin xyz="0 0.1 -0.05" rpy="0 0 0"/>
            <inertia ixx="1570" ixy="0.0" ixz="0.0" iyy="230" iyz="0.0" izz="1600"/>
        </inertial>
        <visual>
            <geometry>
                <mesh filename="./components/body.stl" scale="1 1 1"/>
            </geometry>
            <material name="body_color"/>
        </visual>
        <collision>
            <geometry>
                <mesh filename="./components/body.stl" scale="1 1 1"/>
            </geometry>
        </collision>
    </link>

    <!--* Steering link -->
    <link name="steering_fl">
        <inertial>
            <mass value="0.5"/>
            <inertia ixx="0.005" iyy="0.005" izz="0.005"/>
        </inertial>
    </link>

    <link name="steering_fr">
        <inertial>
            <mass value="0.5"/>
            <inertia ixx="0.005" iyy="0.005" izz="0.005"/>
        </inertial>
    </link>

    <link name="steering_rl">
        <inertial>
            <mass value="0.5"/>
            <inertia ixx="0.005" iyy="0.005" izz="0.005"/>
        </inertial>
    </link>

    <link name="steering_rr">
        <inertial>
            <mass value="0.5"/>
            <inertia ixx="0.005" iyy="0.005" izz="0.005"/>
        </inertial>
    </link>
    
    <!--* Wheel Link -->
    <link name="wheel_fl">
        <inertial>
            <mass value="10.0"/>
            <inertia ixx="1.25" ixy="0.0" ixz="0.0" iyy="0.794" iyz="0.0" izz="0.794"/>
        </inertial>
        <visual>
            <geometry>
                <mesh filename="./components/wheel_FL.stl" scale="1 1 1"/>
            </geometry>
            <material name="tire_color"/>
        </visual>
        <collision>
            <geometry>
                <mesh filename="./components/wheel_FL.stl" scale="1 1 1"/>
            </geometry>
        </collision>
    </link>

    <link name="wheel_fr">
        <inertial>
            <mass value="10.0"/>
            <inertia ixx="1.25" ixy="0.0" ixz="0.0" iyy="0.794" iyz="0.0" izz="0.794"/>
        </inertial>
        <visual>
            <geometry>
                <mesh filename="./components/wheel_FR.stl" scale="1 1 1"/>
            </geometry>
            <material name="tire_color"/>
        </visual>
        <collision>
            <geometry>
                <mesh filename="./components/wheel_FR.stl" scale="1 1 1"/>
            </geometry>
        </collision>
    </link>

    <link name="wheel_rl">
        <inertial>
            <mass value="10.0"/>
            <inertia ixx="1.25" ixy="0.0" ixz="0.0" iyy="0.794" iyz="0.0" izz="0.794"/>
        </inertial>
        <visual>
            <geometry>
                <mesh filename="./components/wheel_RL.stl" scale="1 1 1"/>
            </geometry>
            <material name="tire_color"/>
        </visual>
        <collision>
            <geometry>
                <mesh filename="./components/wheel_RL.stl" scale="1 1 1"/>
            </geometry>
        </collision>
    </link>

    <link name="wheel_rr">
        <inertial>
            <mass value="10.0"/>
            <inertia ixx="1.25" ixy="0.0" ixz="0.0" iyy="0.794" iyz="0.0" izz="0.794"/>
        </inertial>
        <visual>
            <geometry>
                <mesh filename="./components/wheel_RR.stl" scale="1 1 1"/>
            </geometry>
            <material name="tire_color"/>
        </visual>
        <collision>
            <geometry>
                <mesh filename="./components/wheel_RR.stl" scale="1 1 1"/>
            </geometry>
        </collision>
    </link>


    <!-- ======================== -->
    <!--     FRONT LEFT WHEEL     -->
    <!-- ======================== -->
    <!--* Steering Joint -->
    <joint name="steer_joint_fl" type="revolute">
        <origin xyz="-1.05 1.4 0.09" rpy="0.0 0.0 0.0"/>
        <parent link="body"/>
        <child link="steering_fl"/>
        <axis xyz="0.0 0.0 1.0"/>
        <limit lower="-0.5" upper="0.5" effort="80" velocity="100"/>
    </joint>

    <!--* Wheel joint -->
    <joint name="wheel_joint_fl" type="continuous">
        <parent link="steering_fl"/>
        <child link="wheel_fl"/>
        <axis xyz="1.0 0.0 0.0"/>
        <dynamics damping="0.1" friction="0.05"/>
    </joint>

    <!-- ========================= -->
    <!--     FRONT RIGHT WHEEL     -->
    <!-- ========================= -->
    <!--* Steering Joint -->
    <joint name="steer_joint_fr" type="revolute">
        <origin xyz="1.05 1.4 0.09" rpy="0.0 0.0 0.0"/>
        <parent link="body"/>
        <child link="steering_fr"/>
        <axis xyz="0.0 0.0 1.0"/>
        <limit lower="-0.5" upper="0.5" effort="80" velocity="100"/>
    </joint>

    <!--* Wheel joint -->
    <joint name="wheel_joint_fr" type="continuous">
        <parent link="steering_fr"/>
        <child link="wheel_fr"/>
        <axis xyz="1.0 0.0 0.0"/>
        <dynamics damping="0.1" friction="0.05"/>
    </joint>

    <!-- ======================= -->
    <!--     RESR LEFT WHEEL     -->
    <!-- ======================= -->
    <!--* Steering Joint -->
    <joint name="steer_joint_rl" type="fixed">
        <origin xyz="-1.05 -1.5 0.12" rpy="0.0 0.0 0.0"/>
        <parent link="body"/>
        <child link="steering_rl"/>
    </joint>

    <!--* Wheel joint -->
    <joint name="wheel_joint_rl" type="continuous">
        <parent link="steering_rl"/>
        <child link="wheel_rl"/>
        <axis xyz="1.0 0.0 0.0"/>
        <dynamics damping="0.1" friction="0.05"/>
    </joint>

    <!-- ======================== -->
    <!--     REAR RIGHT WHEEL     -->
    <!-- ======================== -->
    <!--* Steering Joint -->
    <joint name="steer_joint_rr" type="fixed">
        <origin xyz="1.05 -1.5 0.12" rpy="0.0 0.0 0.0"/>
        <parent link="body"/>
        <child link="steering_rr"/>
    </joint>

    <!--* Wheel joint -->
    <joint name="wheel_joint_rr" type="continuous">
        <parent link="steering_rr"/>
        <child link="wheel_rr"/>
        <axis xyz="1.0 0.0 0.0"/>
        <dynamics damping="0.1" friction="0.05"/>
    </joint>
</robot>